Workbook

Sheet Сводная
A1: Онлайн-сервисы для России: 34 идеи, которые можно сделать с Claude Code (срез на 20.10.2026)
A2: Синие ячейки и цветные столбцы «Тип», «Конкуренция в РФ», «Регуляторный риск» — экспертные оценки, их можно менять (в цветных столбцах — выпадающие списки).
A3: Балл, место и стоимость в рублях считаются формулами; веса — на листе «Веса и шкалы». Подробное описание каждой идеи — на листе «Карточки».
A4: Место | B4: ID | C4: Продукт | D4: Тип | E4: Балл (0–100) | F4: Категория | G4: Аналог в мире | H4: Сложность (1–5) | I4: Стоимость MVP, уровень (1–4) | J4: Стоимость MVP | K4: Срок MVP | L4: Прибыльность (1–5) | M4: Популярность (1–5) | N4: Конкуренция в РФ | O4: Регуляторный риск | P4: Монетизация | Q4: Канал запуска
A5: =RANK(E5,$E$5:$E$38,0)+COUNTIFS($E$5:$E$38,E5,$B$5:$B$38,"<"&B5) -> 1 | B5: N01 | C5: «Прививка от мошенников» — AI-тренажёр звонков | D5: Новое | E5: =IF(SUM('Веса и шкалы'!$C$6:$C$11)=0,0,ROUND(100*('Веса и шкалы'!$C$6*L5/5+'Веса и шкалы'!$C$7*M5/5+'Веса и шкалы'!$C$8*INDEX('Веса и шкалы'!$B$16:$B$19,MATCH(N5,'Веса и шкалы'!$A$16:$A$19,0))+'Веса и шкалы'!$C$9*(6-H5)/5+'Веса и шкалы'!$C$10*(4-I5)/3+'Веса и шкалы'!$C$11*INDEX('Веса и шкалы'!$B$23:$B$25,MATCH(O5,'Веса и шкалы'!$A$23:$A$25,0)))/SUM('Веса и шкалы'!$C$6:$C$11),0)) -> 78 | F5: Семья | G5: Прямых нет (ScamDrill — текстовые симуляции) | H5: 3 | I5: 2 | J5: =CHOOSE(I5,"до 0,3 млн ₽","0,3–1 млн ₽","1–3 млн ₽","3+ млн ₽") -> 0,3–1 млн ₽ | K5: 2–3 мес. | L5: 4 | M5: 4 | N5: Нет | O5: Средний | P5: Семейная подписка, B2B для банков и работодателей | Q5: Приложение, Max, телефония
A6: =RANK(E6,$E$5:$E$38,0)+COUNTIFS($E$5:$E$38,E6,$B$5:$B$38,"<"&B6) -> 2 | B6: N02 | C6: «ЖКХ-аудитор» — проверка квитанций и перерасчёт | D6: Новое | E6: =IF(SUM('Веса и шкалы'!$C$6:$C$11)=0,0,ROUND(100*('Веса и шкалы'!$C$6*L6/5+'Веса и шкалы'!$C$7*M6/5+'Веса и шкалы'!$C$8*INDEX('Веса и шкалы'!$B$16:$B$19,MATCH(N6,'Веса и шкалы'!$A$16:$A$19,0))+'Веса и шкалы'!$C$9*(6-H6)/5+'Веса и шкалы'!$C$10*(4-I6)/3+'Веса и шкалы'!$C$11*INDEX('Веса и шкалы'!$B$23:$B$25,MATCH(O6,'Веса и шкалы'!$A$23:$A$25,0)))/SUM('Веса и шкалы'!$C$6:$C$11),0)) -> 77 | F6: Дом и деньги | G6: Прямых нет | H6: 3 | I6: 2 | J6: =CHOOSE(I6,"до 0,3 млн ₽","0,3–1 млн ₽","1–3 млн ₽","3+ млн ₽") -> 0,3–1 млн ₽ | K6: 2–3 мес. | L6: 3 | M6: 4 | N6: Нет | O6: Низкий | P6: Фримиум, % от возврата, подписка для ТСЖ | Q6: Веб, Max
A7: =RANK(E7,$E$5:$E$38,0)+COUNTIFS($E$5:$E$38,E7,$B$5:$B$38,"<"&B7) -> 3 | B7: M01 | C7: «Слово дня+» — хаб ежедневных головоломок | D7: Есть в мире | E7: =IF(SUM('Веса и шкалы'!$C$6:$C$11)=0,0,ROUND(100*('Веса и шкалы'!$C$6*L7/5+'Веса и шкалы'!$C$7*M7/5+'Веса и шкалы'!$C$8*INDEX('Веса и шкалы'!$B$16:$B$19,MATCH(N7,'Веса и шкалы'!$A$16:$A$19,0))+'Веса и шкалы'!$C$9*(6-H7)/5+'Веса и шкалы'!$C$10*(4-I7)/3+'Веса и шкалы'!$C$11*INDEX('Веса и шкалы'!$B$23:$B$25,MATCH(O7,'Веса и шкалы'!$A$23:$A$25,0)))/SUM('Веса и шкалы'!$C$6:$C$11),0)) -> 76 | F7: Игры | G7: NYT Games (Wordle, Connections) | H7: 1 | I7: 1 | J7: =CHOOSE(I7,"до 0,3 млн ₽","0,3–1 млн ₽","1–3 млн ₽","3+ млн ₽") -> до 0,3 млн ₽ | K7: 2–4 нед. | L7: 3 | M7: 4 | N7: Средняя | O7: Низкий | P7: Реклама, премиум, white-label для СМИ и банков | Q7: Яндекс Игры, VK, Max, веб
A8: =RANK(E8,$E$5:$E$38,0)+COUNTIFS($E$5:$E$38,E8,$B$5:$B$38,"<"&B8) -> 4 | B8: M15 | C8: «Юрист-автомат»: претензии, жалобы, проверка договоров | D8: Есть в мире | E8: =IF(SUM('Веса и шкалы'!$C$6:$C$11)=0,0,ROUND(100*('Веса и шкалы'!$C$6*L8/5+'Веса и шкалы'!$C$7*M8/5+'Веса и шкалы'!$C$8*INDEX('Веса и шкалы'!$B$16:$B$19,MATCH(N8,'Веса и шкалы'!$A$16:$A$19,0))+'Веса и шкалы'!$C$9*(6-H8)/5+'Веса и шкалы'!$C$10*(4-I8)/3+'Веса и шкалы'!$C$11*INDEX('Веса и шкалы'!$B$23:$B$25,MATCH(O8,'Веса и шкалы'!$A$23:$A$25,0)))/SUM('Веса и шкалы'!$C$6:$C$11),0)) -> 76 | F8: Дом и деньги | G8: DoNotPay | H8: 2 | I8: 2 | J8: =CHOOSE(I8,"до 0,3 млн ₽","0,3–1 млн ₽","1–3 млн ₽","3+ млн ₽") -> 0,3–1 млн ₽ | K8: 1,5–3 мес. | L8: 4 | M8: 4 | N8: Низкая | O8: Средний | P8: Оплата за документ, % от возврата | Q8: Веб
A9: =RANK(E9,$E$5:$E$38,0)+COUNTIFS($E$5:$E$38,E9,$B$5:$B$38,"<"&B9) -> 5 | B9: N06 | C9: «AI-тамада» — праздник под ключ про конкретного человека | D9: Новое | E9: =IF(SUM('Веса и шкалы'!$C$6:$C$11)=0,0,ROUND(100*('Веса и шкалы'!$C$6*L9/5+'Веса и шкалы'!$C$7*M9/5+'Веса и шкалы'!$C$8*INDEX('Веса и шкалы'!$B$16:$B$19,MATCH(N9,'Веса и шкалы'!$A$16:$A$19,0))+'Веса и шкалы'!$C$9*(6-H9)/5+'Веса и шкалы'!$C$10*(4-I9)/3+'Веса и шкалы'!$C$11*INDEX('Веса и шкалы'!$B$23:$B$25,MATCH(O9,'Веса и шкалы'!$A$23:$A$25,0)))/SUM('Веса и шкалы'!$C$6:$C$11),0)) -> 74 | F9: Досуг | G9: Только генераторы тостов | H9: 2 | I9: 1 | J9: =CHOOSE(I9,"до 0,3 млн ₽","0,3–1 млн ₽","1–3 млн ₽","3+ млн ₽") -> до 0,3 млн ₽ | K9: 1–2 мес. | L9: 3 | M9: 3 | N9: Низкая | O9: Низкий | P9: Оплата за праздник, подписка для ведущих | Q9: Веб
A10: =RANK(E10,$E$5:$E$38,0)+COUNTIFS($E$5:$E$38,E10,$B$5:$B$38,"<"&B10) -> 6 | B10: N03 | C10: «AI-прораб» — смета, приёмка, претензии | D10: Новое | E10: =IF(SUM('Веса и шкалы'!$C$6:$C$11)=0,0,ROUND(100*('Веса и шкалы'!$C$6*L10/5+'Веса и шкалы'!$C$7*M10/5+'Веса и шкалы'!$C$8*INDEX('Веса и шкалы'!$B$16:$B$19,MATCH(N10,'Веса и шкалы'!$A$16:$A$19,0))+'Веса и шкалы'!$C$9*(6-H10)/5+'Веса и шкалы'!$C$10*(4-I10)/3+'Веса и шкалы'!$C$11*INDEX('Веса и шкалы'!$B$23:$B$25,MATCH(O10,'Веса и шкалы'!$A$23:$A$25,0)))/SUM('Веса и шкалы'!$C$6:$C$11),0)) -> 73 | F10: Дом и деньги | G10: Частично: проверка смет «Вс на стройку» | H10: 3 | I10: 2 | J10: =CHOOSE(I10,"до 0,3 млн ₽","0,3–1 млн ₽","1–3 млн ₽","3+ млн ₽") -> 0,3–1 млн ₽ | K10: 2–3 мес. | L10: 4 | M10: 3 | N10: Низкая | O10: Низкий | P10: Разовые проверки, подписка, лиды бригадам | Q10: Веб, RuStore
A11: =RANK(E11,$E$5:$E$38,0)+COUNTIFS($E$5:$E$38,E11,$B$5:$B$38,"<"&B11) -> 7 | B11: M03 | C11: AI-алхимия «Бесконечное ремесло» | D11: Есть в мире | E11: =IF(SUM('Веса и шкалы'!$C$6:$C$11)=0,0,ROUND(100*('Веса и шкалы'!$C$6*L11/5+'Веса и шкалы'!$C$7*M11/5+'Веса и шкалы'!$C$8*INDEX('Веса и шкалы'!$B$16:$B$19,MATCH(N11,'Веса и шкалы'!$A$16:$A$19,0))+'Веса и шкалы'!$C$9*(6-H11)/5+'Веса и шкалы'!$C$10*(4-I11)/3+'Веса и шкалы'!$C$11*INDEX('Веса и шкалы'!$B$23:$B$25,MATCH(O11,'Веса и шкалы'!$A$23:$A$25,0)))/SUM('Веса и шкалы'!$C$6:$C$11),0)) -> 72 | F11: Игры | G11: Infinite Craft | H11: 1 | I11: 1 | J11: =CHOOSE(I11,"до 0,3 млн ₽","0,3–1 млн ₽","1–3 млн ₽","3+ млн ₽") -> до 0,3 млн ₽ | K11: 1–3 нед. | L11: 2 | M11: 3 | N11: Низкая | O11: Низкий | P11: Реклама, подсказки | Q11: Яндекс Игры, VK
A12: =RANK(E12,$E$5:$E$38,0)+COUNTIFS($E$5:$E$38,E12,$B$5:$B$38,"<"&B12) -> 8 | B12: M18 | C12: AI-планировщик путешествий по России | D12: Есть в мире | E12: =IF(SUM('Веса и шкалы'!$C$6:$C$11)=0,0,ROUND(100*('Веса и шкалы'!$C$6*L12/5+'Веса и шкалы'!$C$7*M12/5+'Веса и шкалы'!$C$8*INDEX('Веса и шкалы'!$B$16:$B$19,MATCH(N12,'Веса и шкалы'!$A$16:$A$19,0))+'Веса и шкалы'!$C$9*(6-H12)/5+'Веса и шкалы'!$C$10*(4-I12)/3+'Веса и шкалы'!$C$11*INDEX('Веса и шкалы'!$B$23:$B$25,MATCH(O12,'Веса и шкалы'!$A$23:$A$25,0)))/SUM('Веса и шкалы'!$C$6:$C$11),0)) -> 72 | F12: Путешествия | G12: Wanderlog, Mindtrip | H12: 3 | I12: 2 | J12: =CHOOSE(I12,"до 0,3 млн ₽","0,3–1 млн ₽","1–3 млн ₽","3+ млн ₽") -> 0,3–1 млн ₽ | K12: 2–3 мес. | L12: 3 | M12: 4 | N12: Низкая | O12: Низкий | P12: Партнёрские комиссии за бронирования | Q12: Веб, RuStore
A13: =RANK(E13,$E$5:$E$38,0)+COUNTIFS($E$5:$E$38,E13,$B$5:$B$38,"<"&B13) -> 9 | B13: N04 | C13: «Мафия» с AI-игроками и AI-ведущим | D13: Новое | E13: =IF(SUM('Веса и шкалы'!$C$6:$C$11)=0,0,ROUND(100*('Веса и шкалы'!$C$6*L13/5+'Веса и шкалы'!$C$7*M13/5+'Веса и шкалы'!$C$8*INDEX('Веса и шкалы'!$B$16:$B$19,MATCH(N13,'Веса и шкалы'!$A$16:$A$19,0))+'Веса и шкалы'!$C$9*(6-H13)/5+'Веса и шкалы'!$C$10*(4-I13)/3+'Веса и шкалы'!$C$11*INDEX('Веса и шкалы'!$B$23:$B$25,MATCH(O13,'Веса и шкалы'!$A$23:$A$25,0)))/SUM('Веса и шкалы'!$C$6:$C$11),0)) -> 72 | F13: Игры | G13: Только исследования (Werewolf Arena) | H13: 3 | I13: 2 | J13: =CHOOSE(I13,"до 0,3 млн ₽","0,3–1 млн ₽","1–3 млн ₽","3+ млн ₽") -> 0,3–1 млн ₽ | K13: 2–3 мес. | L13: 3 | M13: 4 | N13: Низкая | O13: Низкий | P13: Премиум, подписка, реклама | Q13: Мини-приложение VK/Max, Яндекс Игры
A14: =RANK(E14,$E$5:$E$38,0)+COUNTIFS($E$5:$E$38,E14,$B$5:$B$38,"<"&B14) -> 10 | B14: M02 | C14: Party-игры с телефонами вместо пультов | D14: Есть в мире | E14: =IF(SUM('Веса и шкалы'!$C$6:$C$11)=0,0,ROUND(100*('Веса и шкалы'!$C$6*L14/5+'Веса и шкалы'!$C$7*M14/5+'Веса и шкалы'!$C$8*INDEX('Веса и шкалы'!$B$16:$B$19,MATCH(N14,'Веса и шкалы'!$A$16:$A$19,0))+'Веса и шкалы'!$C$9*(6-H14)/5+'Веса и шкалы'!$C$10*(4-I14)/3+'Веса и шкалы'!$C$11*INDEX('Веса и шкалы'!$B$23:$B$25,MATCH(O14,'Веса и шкалы'!$A$23:$A$25,0)))/SUM('Веса и шкалы'!$C$6:$C$11),0)) -> 71 | F14: Игры | G14: Jackbox Games | H14: 2 | I14: 2 | J14: =CHOOSE(I14,"до 0,3 млн ₽","0,3–1 млн ₽","1–3 млн ₽","3+ млн ₽") -> 0,3–1 млн ₽ | K14: 1,5–3 мес. | L14: 3 | M14: 3 | N14: Низкая | O14: Низкий | P14: Паки игр, лицензии на корпоративы | Q14: Веб/Smart TV, VK Play
A15: =RANK(E15,$E$5:$E$38,0)+COUNTIFS($E$5:$E$38,E15,$B$5:$B$38,"<"&B15) -> 11 | B15: M08 | C15: «Семейная книга» — воспоминания родителей в печатной книге | D15: Есть в мире | E15: =IF(SUM('Веса и шкалы'!$C$6:$C$11)=0,0,ROUND(100*('Веса и шкалы'!$C$6*L15/5+'Веса и шкалы'!$C$7*M15/5+'Веса и шкалы'!$C$8*INDEX('Веса и шкалы'!$B$16:$B$19,MATCH(N15,'Веса и шкалы'!$A$16:$A$19,0))+'Веса и шкалы'!$C$9*(6-H15)/5+'Веса и шкалы'!$C$10*(4-I15)/3+'Веса и шкалы'!$C$11*INDEX('Веса и шкалы'!$B$23:$B$25,MATCH(O15,'Веса и шкалы'!$A$23:$A$25,0)))/SUM('Веса и шкалы'!$C$6:$C$11),0)) -> 71 | F15: Семья | G15: StoryWorth, Remento | H15: 2 | I15: 2 | J15: =CHOOSE(I15,"до 0,3 млн ₽","0,3–1 млн ₽","1–3 млн ₽","3+ млн ₽") -> 0,3–1 млн ₽ | K15: 1–2 мес. | L15: 3 | M15: 3 | N15: Низкая | O15: Низкий | P15: Подарок 5–10 тыс. ₽ | Q15: Веб, Max
A16: =RANK(E16,$E$5:$E$38,0)+COUNTIFS($E$5:$E$38,E16,$B$5:$B$38,"<"&B16) -> 12 | B16: M11 | C16: AI-тренер собеседований и выступлений | D16: Есть в мире | E16: =IF(SUM('Веса и шкалы'!$C$6:$C$11)=0,0,ROUND(100*('Веса и шкалы'!$C$6*L16/5+'Веса и шкалы'!$C$7*M16/5+'Веса и шкалы'!$C$8*INDEX('Веса и шкалы'!$B$16:$B$19,MATCH(N16,'Веса и шкалы'!$A$16:$A$19,0))+'Веса и шкалы'!$C$9*(6-H16)/5+'Веса и шкалы'!$C$10*(4-I16)/3+'Веса и шкалы'!$C$11*INDEX('Веса и шкалы'!$B$23:$B$25,MATCH(O16,'Веса и шкалы'!$A$23:$A$25,0)))/SUM('Веса и шкалы'!$C$6:$C$11),0)) -> 71 | F16: Образование | G16: Yoodli, Interview Warmup | H16: 2 | I16: 2 | J16: =CHOOSE(I16,"до 0,3 млн ₽","0,3–1 млн ₽","1–3 млн ₽","3+ млн ₽") -> 0,3–1 млн ₽ | K16: 1–2 мес. | L16: 3 | M16: 3 | N16: Низкая | O16: Низкий | P16: Подписка, B2B для вузов и онлайн-школ | Q16: Веб
... A38: =RANK(E38,$E$5:$E$38,0)+COUNTIFS($E$5:$E$38,E38,$B$5:$B$38,"<"&B38) -> 34 | B38: M23 | C38: Голосовой AI-администратор для малого бизнеса | D38: Есть в мире | E38: =IF(SUM('Веса и шкалы'!$C$6:$C$11)=0,0,ROUND(100*('Веса и шкалы'!$C$6*L38/5+'Веса и шкалы'!$C$7*M38/5+'Веса и шкалы'!$C$8*INDEX('Веса и шкалы'!$B$16:$B$19,MATCH(N38,'Веса и шкалы'!$A$16:$A$19,0))+'Веса и шкалы'!$C$9*(6-H38)/5+'Веса и шкалы'!$C$10*(4-I38)/3+'Веса и шкалы'!$C$11*INDEX('Веса и шкалы'!$B$23:$B$25,MATCH(O38,'Веса и шкалы'!$A$23:$A$25,0)))/SUM('Веса и шкалы'!$C$6:$C$11),0)) -> 57 | F38: B2B | G38: Goodcall, Slang.ai | H38: 4 | I38: 3 | J38: =CHOOSE(I38,"до 0,3 млн ₽","0,3–1 млн ₽","1–3 млн ₽","3+ млн ₽") -> 1–3 млн ₽ | K38: 3–5 мес. | L38: 4 | M38: 3 | N38: Средняя | O38: Средний | P38: B2B-подписка за точку | Q38: Прямые продажи, маркетплейсы YCLIENTS/amoCRM

Sheet Карточки
A1: ID | B1: Продукт | C1: Тип | D1: Место | E1: Балл | F1: Аналог в мире | G1: Аналоги (подробно) | H1: Что это | I1: Зачем | J1: Почему взлетит в России | K1: Конкуренты | L1: Как сделать | M1: Как зарабатывать | N1: Риски | O1: Ссылки
A2: M01 | B2: «Слово дня+» — хаб ежедневных головоломок | C2: =INDEX(Сводная!$D$5:$D$38,MATCH(A2,Сводная!$B$5:$B$38,0)) -> Есть в мире | D2: =INDEX(Сводная!$A$5:$A$38,MATCH(A2,Сводная!$B$5:$B$38,0)) -> 3 | E2: =INDEX(Сводная!$E$5:$E$38,MATCH(A2,Сводная!$B$5:$B$38,0)) -> 76 | F2: NYT Games (Wordle, Connections) | G2: NYT Games (Wordle, Connections, Strands, Spelling Bee) | H2: Каждый день выходят 4–5 коротких головоломок на 2–5 минут. Угадать слово из 5 букв. Разложить 16 слов на 4 скрытые группы («Связи»). Найти слова в сетке букв. Собрать как можно больше слов из 7 букв («Пчела»). Задания одинаковые для всех, поэтому результат можно сравнить с друзьями и поделиться им. | I2: Ежедневный ритуал на 5 минут, «зарядка для мозга» и повод для общения. | J2: Сильная культура кроссвордов и сканвордов. Спрос доказан: в «5 букв» Т-Банка за два года сыграли больше 7 млн человек и 131 млн партий (Т—Ж). Но там это функция внутри банка, а отдельного хаба нескольких ежедневных игр на русском нет. Механик вроде «Связей» по-русски почти никто не делает. Ядро аудитории Яндекс Игр (35–44 года) как раз любит словесные игры. | K2: «5 букв» Т-Банка, клоны Wordle, приложения со сканвордами. Хаба уровня NYT нет. | L2: PWA, версии для Яндекс Игр, VK Mini Apps и Max. Словари — OpenCorpora (открытая лицензия). Черновики «Связей» генерирует LLM, финальный вид — за человеком-редактором. Бэкенд элементарный: одна головоломка в день. | M2: Реклама в Яндекс Играх, премиум за 149 ₽ в месяц (архив, статистика, без рекламы). Главное — B2B: продавать white-label-виджет СМИ, банкам и ритейлерам ради ежедневных заходов, как сделал Т-Банк. Ради того же NYT купил Wordle. | N2: Клон можно сделать за неделю. Защищают качество редактуры, сообщество и B2B-контракты. | O2: https://t-j.ru/5bukv-game-stat/
A3: M02 | B3: Party-игры с телефонами вместо пультов | C3: =INDEX(Сводная!$D$5:$D$38,MATCH(A3,Сводная!$B$5:$B$38,0)) -> Есть в мире | D3: =INDEX(Сводная!$A$5:$A$38,MATCH(A3,Сводная!$B$5:$B$38,0)) -> 10 | E3: =INDEX(Сводная!$E$5:$E$38,MATCH(A3,Сводная!$B$5:$B$38,0)) -> 71 | F3: Jackbox Games | G3: Jackbox Games | H3: Игра запускается на телевизоре или ноутбуке, гости подключаются с телефонов по коду комнаты, ничего не устанавливая. Примеры: придумать смешной ответ на вопрос и выдать его за правду; нарисовать слово, чтобы другие угадали; угадать, кто из друзей что написал. | I3: Развлечение для вечеринок, семейных праздников, корпоративов и стримов. | J3: Игры Jackbox только на английском (Jackbox). При этом в России огромная культура квизов («Квиз, плиз!», «Мозгобойня»), корпоративов и новогодних застолий. Русский юмор не переводится, нужен свой контент. | K3: Прямых русскоязычных аналогов не нашёл. Kahoot- и AhaSlides-подобные сервисы — это викторины для презентаций, а не party-игры. | L3: Веб (Next.js) + WebSocket-сервер комнат. На Smart TV — через браузер. LLM генерирует черновики заданий, редакторы-юмористы их правят. Claude Code хорошо пишет такую real-time-логику. | M3: Паки игр по 299–699 ₽. Лицензия на корпоратив — 5–30 тыс. ₽ за мероприятие. Подписка для баров и квиз-ведущих. | N3: Всё решает качество юмора. Сильная сезонность с пиком в декабре. | O3: https://www.jackboxgames.com/how-to
A4: M03 | B4: AI-алхимия «Бесконечное ремесло» | C4: =INDEX(Сводная!$D$5:$D$38,MATCH(A4,Сводная!$B$5:$B$38,0)) -> Есть в мире | D4: =INDEX(Сводная!$A$5:$A$38,MATCH(A4,Сводная!$B$5:$B$38,0)) -> 7 | E4: =INDEX(Сводная!$E$5:$E$38,MATCH(A4,Сводная!$B$5:$B$38,0)) -> 72 | F4: Infinite Craft | G4: Infinite Craft (neal.fun) | H4: На старте есть 4 элемента: вода, огонь, земля, воздух. Соединяешь любые два, и нейросеть придумывает результат: огонь + вода = пар → … → «Кощей Бессмертный», «Пятиэтажка», «Ипотека». Комбинаций бесконечно много, а «первое в мире открытие» отмечается в игре. | I4: Залипательная песочница и вирусные ролики «как я скрафтил…». | J4: Русская культура даёт уникальные комбинации из мемов, сказок и советских реалий, а это готовые ролики для VK Клипов. Механика «Алхимии» без AI на Яндекс Играх давно популярна. | K4: Старые «Алхимии» и Doodle God без AI. Русского AI-аналога не нашёл. | L4: Каждая пара элементов генерируется один раз для всех игроков и кэшируется в базе, поэтому расходы на LLM со временем падают. Хватит самой дешёвой модели (≈0,065 ₽ за 1000 токенов). MVP — 1–3 недели. | M4: Реклама за вознаграждение, платные подсказки. Доход с игрока низкий, зато и себестоимость почти нулевая. | N4: Модерация: нейросеть может «скрафтить» запрещённое, поэтому нужны фильтр и стоп-лист. Хайп проходит быстро, нужны регулярные ивенты. | O4: —
A5: M04 | B5: «Где это?» — угадай место по панорамам России | C5: =INDEX(Сводная!$D$5:$D$38,MATCH(A5,Сводная!$B$5:$B$38,0)) -> Есть в мире | D5: =INDEX(Сводная!$A$5:$A$38,MATCH(A5,Сводная!$B$5:$B$38,0)) -> 27 | E5: =INDEX(Сводная!$E$5:$E$38,MATCH(A5,Сводная!$B$5:$B$38,0)) -> 62 | F5: GeoGuessr | G5: GeoGuessr | H5: Показывают панораму улицы, нужно поставить точку на карте: чем ближе, тем больше очков. Режимы: «Вся Россия», «Мой город», «Дуэль с другом», «Города СССР». | I5: Игра, которая заодно учит знать свою страну. GeoGuessr используют даже на уроках географии (Naked Science). | J5: GeoGuessr построен на Google Street View, и оплатить его из РФ нельзя. Аналога на панорамах России не нашёл. Внутренний туризм растёт, у регионов есть бюджеты на продвижение, отсюда спонсорские «туры по региону». | K5: GeoGuessr (без оплаты из РФ) и мелкие клоны. | L5: Панорамы через API Яндекс Карт (нужна коммерческая лицензия) или открытые фото Mapillary. Веб-версия + Яндекс Игры. | M5: Реклама и премиум. B2B: школы, туристические ведомства регионов (спонсорские карты), бренды. | N5: Главный вопрос — лицензия на панорамы. Условия нужно проверить до старта. | O5: https://naked-science.ru/article/media/onlaine-game-geoguessr
A6: M05 | B6: «Хрущёвка: ремонт мечты» — ностальгическая merge-игра | C6: =INDEX(Сводная!$D$5:$D$38,MATCH(A6,Сводная!$B$5:$B$38,0)) -> Есть в мире | D6: =INDEX(Сводная!$A$5:$A$38,MATCH(A6,Сводная!$B$5:$B$38,0)) -> 19 | E6: =INDEX(Сводная!$E$5:$E$38,MATCH(A6,Сводная!$B$5:$B$38,0)) -> 68 | F6: Homescapes, Merge Mansion | G6: Homescapes, Merge Mansion, Travel Town | H6: Соединяешь одинаковые предметы (2 кирпича → стена, 2 куска обоев → рулон) и так ремонтируешь советскую квартиру или дачу: ковёр на стене, сервант с хрусталём, телевизор «Рубин». Сюжет держится на историях соседей по подъезду. | I6: Казуальная игра на 5–15 минут, которая зарабатывает на покупках внутри. | J6: Ядро аудитории Яндекс Игр (35–44 года) сильно ностальгирует по СССР. Merge и «ремонт» — одни из самых доходных жанров мобильных игр в мире. Homescapes сделала Playrix, основанная выходцами из России, но покупки из РФ там затруднены. Ностальгического сеттинга нет ни у кого. | K6: Жанр переполнен, но этот сеттинг свободен. | L6: Phaser, PixiJS или Cocos. Claude Code пишет логику, экономику и панель управления ивентами. Арт генерирует нейросеть (например, Kandinsky), а художник приводит его к единому стилю. | M6: Покупки в игре (Яндекс Игры принимают российские карты) и реклама за вознаграждение. | N6: Самая дорогая из игровых идей: нужны регулярные обновления контента и тонкий баланс экономики. Без удержания игроков денег не будет. | O6: —
A7: M06 | B7: Счётчик калорий по фото еды | C7: =INDEX(Сводная!$D$5:$D$38,MATCH(A7,Сводная!$B$5:$B$38,0)) -> Есть в мире | D7: =INDEX(Сводная!$A$5:$A$38,MATCH(A7,Сводная!$B$5:$B$38,0)) -> 15 | E7: =INDEX(Сводная!$E$5:$E$38,MATCH(A7,Сводная!$B$5:$B$38,0)) -> 70 | F7: Cal AI | G7: Cal AI, одно из самых быстрорастущих приложений 2024–2025 годов | H7: Фотографируешь тарелку, приложение распознаёт блюдо и оценивает калории и БЖУ. Плюс дневник, цели и вес. | I7: Считать калории вручную долго и скучно, поэтому большинство бросает. | J7: ЗОЖ в тренде, аудитория FatSecret и YAZIO огромная, а Cal AI нельзя оплатить из РФ. Отличиться можно базой русской кухни и меню сетей (столовые, «Теремок», «Вкусно — и точка») и загрузкой чеков из доставок. | K7: Растут: в RuStore уже есть «Калорика AI», FoodWarz, «ЗОЖ» (RuStore), плюс FatSecret. Побеждать придётся качеством и маркетингом. | L7: React Native/Expo. Распознавание — open-source VLM (Qwen-VL) на своём GPU или российский API. База продуктов. | M7: Подписка 299–599 ₽ в месяц. Распознавание одного фото стоит копейки, максимум рубли. | N7: Точность по фото ограничена: масла и соусов не видно. Погрешность нужно честно показывать, медицинских советов не давать. | O7: https://www.rustore.ru/catalog/app/com.nutrisync.advanced
A8: M07 | B8: Ужины с незнакомцами «Шестеро» | C8: =INDEX(Сводная!$D$5:$D$38,MATCH(A8,Сводная!$B$5:$B$38,0)) -> Есть в мире | D8: =INDEX(Сводная!$A$5:$A$38,MATCH(A8,Сводная!$B$5:$B$38,0)) -> 21 | E8: =INDEX(Сводная!$E$5:$E$38,MATCH(A8,Сводная!$B$5:$B$38,0)) -> 67 | F8: Timeleft | G8: Timeleft (275 городов в 62 странах) | H8: Проходишь психологический тест. В выбранный день алгоритм собирает в ресторане стол из 6 подходящих друг другу людей. Это не свидания, а знакомство с новыми друзьями (Tasting Table). | I8: В больших городах после 25–30 лет трудно заводить друзей, а переезжающих много. | J8: Timeleft в России не работает. Спрос на «знакомства для дружбы» показали Random Coffee-боты, а ресторанам выгодны гости в будни. | K8: Мелкие локальные форматы вроде тайных ужинов Stay Hungry (Афиша), чаты по интересам. | L8: Мини-приложение в Max/VK + веб, алгоритм подбора, оплата, кабинет ресторана. Для безопасности — верификация через Госуслуги, Сбер ID или T-ID. | M8: Подписка 990–1 990 ₽ в месяц или 590–990 ₽ за ужин, плюс бонусы от ресторанов. | N8: Безопасность офлайн-встреч. Запуск каждого города — ручная работа. Возможно, придётся соответствовать закону о платформенной экономике. | O8: https://www.tastingtable.com/1859085/dinner-parties-with-strangers-timeleft https://daily.afisha.ru/archive/gorod/archive/behind-stay-hungry/
A9: M08 | B9: «Семейная книга» — воспоминания родителей в печатной книге | C9: =INDEX(Сводная!$D$5:$D$38,MATCH(A9,Сводная!$B$5:$B$38,0)) -> Есть в мире | D9: =INDEX(Сводная!$A$5:$A$38,MATCH(A9,Сводная!$B$5:$B$38,0)) -> 11 | E9: =INDEX(Сводная!$E$5:$E$38,MATCH(A9,Сводная!$B$5:$B$38,0)) -> 71 | F9: StoryWorth, Remento | G9: StoryWorth, Remento, Storii | H9: Раз в неделю маме, папе или бабушке приходит вопрос: «Как вы познакомились с дедушкой?», «Каким был ваш первый рабочий день?». Отвечать можно голосом, сервис расшифрует запись и бережно отредактирует. Через год получается печатная книга с фотографиями (Storii). | I9: Сохранить истории семьи, пока это ещё возможно. Отличный подарок. | J9: Сильная культура семейной памяти, растёт интерес к родословной. Повод для покупки — юбилей, Новый год, 8 Марта. Сейчас есть только биографы на заказ за десятки и сотни тысяч рублей. | K9: Прямых русскоязычных нет. | L9: Вопросы через Max, SMS или звонок робота. Распознавание речи (GigaAM, SaluteSpeech). LLM редактирует текст литературно, но сохраняет голос автора. Вёрстка PDF, печать — у партнёра по фотокнигам. | M9: 4 990–9 990 ₽ за год, включая одну книгу. Дополнительные экземпляры — 1 500–2 500 ₽. Высокий средний чек, пики продаж к праздникам. | N9: Персональные данные (нужны согласия), качество печати и доставка. | O9: https://storii.com/blog/storyworth
A10: M09 | B10: «Собеседник» — AI-звонки пожилым родителям | C10: =INDEX(Сводная!$D$5:$D$38,MATCH(A10,Сводная!$B$5:$B$38,0)) -> Есть в мире | D10: =INDEX(Сводная!$A$5:$A$38,MATCH(A10,Сводная!$B$5:$B$38,0)) -> 16 | E10: =INDEX(Сводная!$E$5:$E$38,MATCH(A10,Сводная!$B$5:$B$38,0)) -> 70 | F10: Joy Calls, Meela | G10: Joy Calls, Meela, CallieCare (США) | H10: В условленное время AI-голос звонит пожилому человеку на обычный телефон, даже кнопочный. Разговаривает о жизни, напоминает о лекарствах, помнит прошлые беседы. Семье приходит короткий отчёт: «настроение хорошее, жаловалась на давление, просила позвонить внучке» (Joy Calls, Meela). | I10: Против одиночества пожилых и тревоги взрослых детей, которые живут далеко. | J10: Около 40 млн пенсионеров, а дети массово уезжают в крупные города. Плюс угроза мошенников: AI заметит фразу «мне звонили из банка» и предупредит семью (это связка с N01). Аналогов в России не нашёл. | K10: Прямых нет. Смежные — уведомления МТС семье о нежелательном звонке (Rozetked) и приложения-определители номера. | L10: Телефония (Voximplant, MTS Exolve), потоковое распознавание речи (T-one, SaluteSpeech), синтез (SpeechKit, Silero), LLM с памятью. Самое сложное — маленькая задержка и естественный голос. | M10: Семейная подписка 990–1 990 ₽ в месяц. B2B: частные пансионаты, соцслужбы, страховые. По моей оценке, 10-минутный звонок обходится примерно в 25–40 ₽ (телефония, распознавание, синтез, LLM). | N10: Данные о здоровье — особая категория персональных данных, нужно письменное согласие. Этика: продукт нужно подавать как дополнение к звонкам семьи, а не как замену. | O10: https://www.homecaremag.com/news/joy-calls-launches-ai-phone-companion-seniors https://www.businesswire.com/news/home/20250911525548/en/Meela-Launches-Personalized-AI-Companion-to-Combat-Loneliness-Epidemic-Among-Seniors https://rozetked.me/index.php/news/47910-analitika-bol-she-poloviny-rossiyan-ispol-zuyut-ii-servisy-cifrovoy-zaschity
A11: M10 | B11: Китайский с AI-тренером тонов | C11: =INDEX(Сводная!$D$5:$D$38,MATCH(A11,Сводная!$B$5:$B$38,0)) -> Есть в мире | D11: =INDEX(Сводная!$A$5:$A$38,MATCH(A11,Сводная!$B$5:$B$38,0)) -> 32 | E11: =INDEX(Сводная!$E$5:$E$38,MATCH(A11,Сводная!$B$5:$B$38,0)) -> 59 | F11: HelloChinese, Praktika | G11: HelloChinese, SuperChinese + Praktika, Speak | H11: Приложение в духе Duolingo, но для китайского и для русскоязычных. Уроки HSK 1–4, тренажёр тонов с графиком высоты твоего голоса, разговорные сценки с AI («поторгуйся с поставщиком на выставке в Гуанчжоу»). | I11: Китайский стал рабочим языком бизнеса, логистики и туризма. | J11: Торговля с Китаем и поездки растут, китайский есть в ЕГЭ. Англоязычные приложения неудобны русскоязычным, а оплатить их сложно. | K11: Laoshi AI (около 195 тыс. учеников) (App Store), онлайн-школы, глобальные приложения. | L11: Expo. Распознавание китайской речи на open-source (FunASR, Whisper) плюс анализ высоты тона. Контент пишет LLM, проверяет носитель языка. | M11: Подписка 490–990 ₽ в месяц. B2B: компании, которые работают с Китаем. | N11: Без носителя-редактора качество контента не обеспечить. Нужно выделиться на фоне онлайн-школ. | O11: https://apps.apple.com/us/app/%D0%BA%D0%B8%D1%82%D0%B0%D0%B9%D1%81%D0%BA%D0%B8%D0%B9-%D1%8F%D0%B7%D1%8B%D0%BA-%D1%81-%D0%BB%D0%B0%D0%BE%D1%88%D0%B8/id1510215770?l=ru
A12: M11 | B12: AI-тренер собеседований и выступлений | C12: =INDEX(Сводная!$D$5:$D$38,MATCH(A12,Сводная!$B$5:$B$38,0)) -> Есть в мире | D12: =INDEX(Сводная!$A$5:$A$38,MATCH(A12,Сводная!$B$5:$B$38,0)) -> 12 | E12: =INDEX(Сводная!$E$5:$E$38,MATCH(A12,Сводная!$B$5:$B$38,0)) -> 71 | F12: Yoodli, Interview Warmup | G12: Yoodli, Google Interview Warmup | H12: AI голосом проводит собеседование под конкретную вакансию с hh.ru и задаёт уточняющие вопросы. Потом разбирает ответы: слова-паразиты, структура, темп, что улучшить. Режимы: собеседование, питч инвестору, разговор о повышении, защита диплома. | I12: Тренироваться на живых людях страшно и дорого, а без тренировки собеседования проваливают. | J12: Рынок труда активный, смена профессии — массовый сценарий, на нём держатся Яндекс Практикум, Skillbox и другие. Качественного русскоязычного тренажёра не нашёл, у hh.ru такой функции нет. | K12: Зарубежные сервисы на английском. | L12: Веб, голос (SpeechKit/SaluteSpeech), LLM с банком вопросов по профессиям, оценка по рубрике. | M12: 490–990 ₽ в месяц. B2B: вузы, онлайн-школы (как модуль трудоустройства), HR-отделы для внутреннего найма. | N12: Нельзя превращать продукт в «подсказчик на реальном собеседовании». | O12: —
A13: M12 | B13: AI-проверка сочинений и задач ЕГЭ/ОГЭ | C13: =INDEX(Сводная!$D$5:$D$38,MATCH(A13,Сводная!$B$5:$B$38,0)) -> Есть в мире | D13: =INDEX(Сводная!$A$5:$A$38,MATCH(A13,Сводная!$B$5:$B$38,0)) -> 13 | E13: =INDEX(Сводная!$E$5:$E$38,MATCH(A13,Сводная!$B$5:$B$38,0)) -> 71 | F13: EssayGrader, Gauth | G13: EssayGrader, Gauth/Photomath | H13: Школьник загружает фото или текст сочинения либо решения из второй части. Через 1–2 минуты получает оценку по критериям ФИПИ, разбор каждой ошибки и задание «исправь сам». | I13: Учитель или репетитор проверяет одно сочинение 20–25 минут и стоит дорого. Писать и исправлять нужно много раз. | J13: Итоговое сочинение и ЕГЭ по русскому пишет каждый 11-классник, ОГЭ сдаёт каждый 9-классник. Родители тратят на подготовку большие деньги. | K13: Рынок формируется, лидера нет. Есть aiПушкин от «ИнтернетУрока» и «Антиплагиата» (больше 9 тыс. проверок) (Yandex Cloud), онлайн-школы с живыми проверяющими, универсальные GigaChat и Алиса. | L13: Распознавание рукописи (VLM), LLM с жёсткой рубрикой и примерами оценённых работ, калибровка на банке реальных сочинений с экспертными оценками. | M13: 99–199 ₽ за проверку или 790–1 490 ₽ в месяц в сезон подготовки. B2B: репетиторы и онлайн-школы (white-label API). | N13: Оценка может быть неточной, поэтому продукт нужно подавать как тренажёр, а не экзамен. Данные несовершеннолетних требуют согласия родителей. | O13: https://yandex.cloud/ru/cases/aipushkin
... A35: N09 | B35: «AI-тайный покупатель» для сетей и франшиз | C35: =INDEX(Сводная!$D$5:$D$38,MATCH(A35,Сводная!$B$5:$B$38,0)) -> Новое | D35: =INDEX(Сводная!$A$5:$A$38,MATCH(A35,Сводная!$B$5:$B$38,0)) -> 25 | E35: =INDEX(Сводная!$E$5:$E$38,MATCH(A35,Сводная!$B$5:$B$38,0)) -> 65 | F35: Классические агентства тайных покупателей | G35: Есть только классические агентства | H35: AI-голос звонит и пишет в компанию под видом клиента по сценарию: «хочу записаться на маникюр завтра», «сколько стоит замена ремня ГРМ». Проверяет, как отвечают сотрудники: скорость, вежливость, следование скрипту, предлагают ли допродажу. Присылает оценку и записи. Тот же механизм позволяет следить за публичными ценами и сроками конкурентов. | I35: Сетям и франшизам нужно контролировать десятки точек, а агентства тайных покупателей дорогие и медленные. | J35: Много франшиз в услугах и общепите, дефицит и текучка персонала, качество сервиса нестабильно. | K35: Классические агентства и речевая аналитика для крупных колл-центров. AI-формата для малого и среднего бизнеса не видел. | L35: — | M35: 5–30 тыс. ₽ в месяц за точку или пакет проверок. | N35: Исходящие звонки подпадают под правила маркировки звонков. Проверять конкурентов этично только по публичной информации. | O35: —

Sheet Веса и шкалы
A1: Веса итогового балла и шкалы оценок
A2: Меняйте жёлтые ячейки (синий шрифт) — балл и место на листе «Сводная» пересчитаются. Значения по умолчанию подобраны под небольшую команду с ограниченным бюджетом.
A5: Критерий | B5: Что оценивает | C5: Вес (ввод) | D5: Доля в балле
A6: Прибыльность | B6: Потенциальная выручка через ~2 года при успехе | C6: 5 | D6: =IF(SUM($C$6:$C$11)=0,0,C6/SUM($C$6:$C$11)) -> 0.25
A7: Популярность | B7: Потенциальный охват пользователей | C7: 4 | D7: =IF(SUM($C$6:$C$11)=0,0,C7/SUM($C$6:$C$11)) -> 0.2
A8: Свобода от конкуренции | B8: Насколько ниша в РФ ещё не занята | C8: 4 | D8: =IF(SUM($C$6:$C$11)=0,0,C8/SUM($C$6:$C$11)) -> 0.2
A9: Простота | B9: Обратная величина сложности реализации | C9: 3 | D9: =IF(SUM($C$6:$C$11)=0,0,C9/SUM($C$6:$C$11)) -> 0.15
A10: Дешевизна | B10: Обратная величина стоимости MVP | C10: 2 | D10: =IF(SUM($C$6:$C$11)=0,0,C10/SUM($C$6:$C$11)) -> 0.1
A11: Регуляторная безопасность | B11: Обратная величина регуляторного риска | C11: 2 | D11: =IF(SUM($C$6:$C$11)=0,0,C11/SUM($C$6:$C$11)) -> 0.1
A12: Итого | C12: =SUM(C6:C11) -> 20 | D12: =SUM(D6:D11) -> 1
A14: Перевод текстовых оценок в доли (0–1)
A15: Конкуренция в РФ | B15: Свобода (0–1)
A16: Нет | B16: 1
A17: Низкая | B17: 0.75
A18: Средняя | B18: 0.5
A19: Высокая | B19: 0.25
A22: Регуляторный риск | B22: Безопасность (0–1)
A23: Низкий | B23: 1
A24: Средний | B24: 0.6
A25: Высокий | B25: 0.2
A28: Формула балла
A29: Балл = ОКРУГЛ(100 × (Вес прибыльности × Прибыльность/5 + Вес популярности × Популярность/5 + Вес конкуренции × Свобода + Вес простоты × (6 − Сложность)/5 + Вес дешевизны × (4 − Уровень стоимости)/3 + Вес безопасности × Безопасность) / Сумма весов). Место — по убыванию балла, при равенстве — по ID.
A31: Шкалы оценок
A32: Шкала | B32: Значения
A33: Сложность (1–5) | B33: 1 — MVP за 1–3 недели одним разработчиком с Claude Code; 2 — 1–2 месяца; 3 — 2–4 месяца, нужны голос/данные/интеграции; 4 — 4–6+ месяцев, сложная технология; 5 — больше 8 месяцев
A34: Стоимость MVP (уровень 1–4) | B34: 1 — до ~300 тыс. ₽; 2 — ~0,3–1 млн ₽; 3 — ~1–3 млн ₽; 4 — больше 3 млн ₽ (деньги до запуска MVP без маркетинга, если код пишет основатель с Claude Code)
A35: Прибыльность (1–5) | B35: Выручка в месяц через ~2 года при успехе: 1 — до 0,5 млн ₽; 2 — 0,5–2 млн; 3 — 2–10 млн; 4 — 10–50 млн; 5 — больше 50 млн
A36: Популярность (1–5) | B36: Потенциальный охват: 1 — до 50 тыс. пользователей; 2 — до 300 тыс.; 3 — до 1–2 млн; 4 — до 5–10 млн; 5 — больше 10 млн (для B2B — доля охваченного рынка)
A37: Конкуренция в РФ | B37: Нет / Низкая / Средняя / Высокая — насколько ниша в РФ уже занята
A38: Регуляторный риск | B38: Низкий / Средний / Высокий — регуляторные и правовые риски в РФ
A40: Методология и ограничения
A41: • Как искали. По каждой идее проверял в октябре 2026 года, есть ли российские аналоги: веб-поиск, RuStore, App Store, отраслевые СМИ. Если пишу «аналогов не нашёл», это значит, что поиск их не выявил. Маленькие проекты могли остаться незамеченными. Перед стартом стоит потратить час на собственную проверку.
A42: • Оценки экспертные, а не прогноз. Прибыльность — это потенциал при успешном исполнении, а не гарантия. Большинство стартапов не доходят до таких цифр.
A43: • Стоимость MVP считалась так: основатель сам пишет код с Claude Code. Если нанимать разработчика, добавьте его зарплату. Маркетинг не учтён, и именно он обычно становится главной статьёй расходов после запуска.
A44: • Данные о рынке (блокировки, законы, цены моделей) меняются быстро. Это срез на 20.10.2026, а часть сведений взята из отраслевых блогов, поэтому ключевые факты нужно перепроверять по первоисточникам.
A45: • Исходные данные лежат в data/ideas.json, формула — в scripts/score.py.

Sheet Кластеры
A1: Кластер | B1: Продукты (→ — порядок запуска) | C1: Кто платит | D1: Почему вместе | E1: Рекомендация
A2: «Забота о родителях» | B2: N01 Прививка от мошенников → M09 Собеседник → M08 Семейная книга → N07 Второй пилот пациента | C2: Взрослые дети 30–55 лет | D2: Один покупатель, одна семейная подписка. Один голосовой AI-движок: звонки, распознавание, память. Есть B2B: банки, работодатели, пансионаты, соцзащита | E2: Рекомендуем начать с него
A3: «Защитник потребителя» | B3: M15 Юрист-автомат + N02 ЖКХ-аудитор + N03 AI-прораб + M16 Помощник должника | C3: Массовый потребитель | D3: Один движок: «шаблон, проверенный юристом, + LLM + отслеживание сроков». Оплата за результат
A4: «Праздники и компании» | B4: M02 Party-игры + N06 AI-тамада + N04 Мафия с AI | C4: Компании друзей, семьи, корпоративы | D4: Один real-time-движок «экран + телефоны», общий контент, пик продаж в декабре
A5: «Экзамены и карьера» | B5: M12 Проверка ЕГЭ/ОГЭ + M11 Тренер собеседований + M10 Китайский | C5: Родители школьников, студенты | D5: Один движок «оценка по рубрике + разбор ошибок». Продажи через онлайн-школы

Sheet Занятые ниши
A1: Ниша (мировой аналог) | B1: Кто уже работает в России | C1: Вывод | D1: Ссылки
A2: Доступ к ChatGPT и Midjourney (агрегаторы нейросетей) | B2: Десятки ботов и сайтов-агрегаторов | C2: Перегрето, демпинг, риски с оплатой зарубежных API | D2: —
A3: Notion, Miro, Slack, Figma | B3: Yonote, Weeek, Kaiten, Пачка, Pixso и др. | C3: Замены появились ещё в 2022–2024 годах | D3: —
A4: Loom (видеосообщения) | B4: Скрини, Глабикс.Экран, TeamStream от МТС бесплатно (a2is, iPhones.ru) | C4: Бесплатный конкурент от крупного игрока | D4: https://a2is.ru/catalog/messendzhery-dlya-komandnoy-raboty/skrini https://www.iphones.ru/iNotes/mts-web-services-otkryla-besplatnyy-dostup-k-servisu-dlya-obmena-asinhronnymi-video
A5: Opus Clip (нарезка шортсов) | B5: MnogoReels, ClipCut, Reels Boss (Sostav) | C5: Уже несколько русскоязычных сервисов | D5: https://www.sostav.ru/blogs/290467/88610
A6: AI-сказки для детей | B6: MySkazka, Kitsy | C6: Ниша занята, дифференцироваться трудно | D6: —
A7: Свадебные сайты-приглашения | B7: Больше 12 конструкторов (vc.ru) | C7: Высокая конкуренция | D7: https://vc.ru/services/3041069-konstruktor-saytov-svadb-privlecheniy
A8: Rover (выгул и передержка собак) | B8: Догси, Профи.ру, Авито | C8: Маркетплейс уже есть, рынок узкий | D8: —
A9: Whering (цифровой гардероб) | B9: КОМОД (RuStore) | C9: Есть игрок, слабая монетизация | D9: https://www.rustore.ru/catalog/app/ru.komod.app
A10: OurFamilyWizard (для разведённых родителей) | B10: «Опора» (RuStore) | C10: Есть игрок, маленькая платящая аудитория | D10: https://www.rustore.ru/catalog/app/click.opora.app
A11: Linktree, Teachable, Fiverr, Airbnb | B11: Taplink, GetCourse, Kwork, Суточно.ру, Островок | C11: Давно заняты сильными локальными игроками | D11: —
A12: Сервисы для селлеров WB и Ozon | B12: MPStats и десятки других | C12: Перенасыщено | D12: —

Sheet Второй эшелон
A1: Идея | B1: Комментарий
A2: Профориентация с AI-симуляцией профессий | B2: Подросток «проживает день» хирурга, программиста или пилота. Минус: конкуренция с госпрограммами вроде «Билета в будущее».
A3: Детектор голосовых дипфейков для семей | B3: Лучше сделать функцией внутри N01, а не отдельным продуктом.
A4: Трекер детского сна с прогнозом «окна сна» (аналог Huckleberry) | B4: Ниша интересная, но спрос не проверял.
A5: Простой планшет-лаунчер для бабушки с удалённым управлением детьми (аналог GrandPad) | B5: Сильная синергия с M09 и N01, но нужно «железо».
A6: Ещё несколько идей | B6: Поиск соседа по квартире (SpareRoom), рейтинг ресторанов среди друзей (Beli), цифровое наследство (GoodTrust), визовый помощник для россиян (Atlys; риски с ботами записи), «позвоню в поддержку за вас» (Pine AI).

Sheet Правила рынка 2026
A1: Тема | B1: Суть | C1: Ссылки
A2: Каналы распространения поменялись | B2: Telegram ограничивают с 10 февраля 2026 года. По ряду оценок, к июню доступ почти полностью заблокирован, хотя, по словам Павла Дурова, им ежедневно продолжают пользоваться 65 млн россиян (Битрикс24, vc.ru). Строить на нём основной канал рискованно. ФАС не штрафует за рекламу в Telegram и YouTube только до конца 2026 года. | C2: https://www.bitrix24.ru/journal/blokirovka-telegram/ https://vc.ru/telegram/2974687-blokirovka-telegram-i-ischeznoveniye-max
A3: Каналы распространения поменялись | B3: WhatsApp под угрозой полной блокировки до конца 2026 года (ppc.world). | C3: https://ppc.world/news/whatsapp-otklyuchat-v-2026-godu-telegram-trogat-ne-budut-deputat-gosdumy/
A4: Каналы распространения поменялись | B4: Max (VK) предустанавливается на смартфоны. С весны 2026 года в нём есть раздел «MAX для бизнеса» с мини-приложениями и оплатой внутри, верификация компаний идёт через Госуслуги (Sostav, Т-Бизнес). Бренды там пока почти не конкурируют. Минус: по данным vc.ru, 4 июня 2026 года Max пропал из App Store. Школьные чаты переводят в Max (Медуза). | C4: https://www.sostav.ru/blogs/292093/95285 https://secrets.tbank.ru/tehnologii/max-dlya-biznesa/ https://meduza.io/news/2025/07/27/kommersant-soobschil-chto-shkolnye-chaty-v-shesti-regionah-rossii-perevedut-v-messendzher-max-v-tatarstane-perehod-podtverdili
A5: Каналы распространения поменялись | B5: Яндекс Игры: по данным самой платформы, около 45 млн игроков в месяц (WN Hub). Есть встроенная реклама и покупки внутри игры за российские карты. Крупнейшая возрастная группа — 35–44 года (Яндекс). Это готовый канал для всех игр из списка. | C5: https://wnhub.io/ru/news/monetization/item-47819 https://yandex.ru/project/games/for-developers
A6: Каналы распространения поменялись | B6: VK (мини-приложения, VK Play, VK Видео), RuStore (предустановлен на Android) и веб/PWA. Веб-версия обязательна, потому что iOS-аудиторию в РФ трудно монетизировать через App Store. | C6: —
A7: Платежи | B7: App Store и Google Play не принимают российские карты (vc.ru). Подписки и разовые платежи принимают через ЮKassa, CloudPayments, Т-Банк, Robokassa, СБП (в том числе рекуррентные), биллинг Яндекс Игр и RuStore. Попутно это значит, что многие западные приложения работают в России, но денег с россиян получить не могут. Это «дыра», которую закрывают локальные аналоги. | C7: https://vc.ru/services/3012698-sposoby-oplaty-podpiski-duolingo-iz-rossii
A8: AI внутри продукта — российский или open-source | B8: Claude Code — инструмент разработчика. Модели, которые отвечают пользователям уже внутри продукта, должны работать в России. Причин три: персональные данные россиян по 152-ФЗ нужно хранить в РФ, крупные зарубежные провайдеры моделей официально не обслуживают Россию, а оплатить их из РФ нельзя. Варианты: | C8: —
A9: AI внутри продукта — российский или open-source | B9: GigaChat API (Сбер): Lite ≈ 0,065 ₽, Pro ≈ 0,50 ₽ за 1000 токенов. YandexGPT: Lite ≈ 0,20 ₽, Pro 5.1 ≈ 0,80 ₽. Цены на август 2026 (3DNews, AdIndex). | C9: https://3dnews.ru/1147409 https://adindex.ru/news/digital/2026/08/25/348304.phtml
A10: AI внутри продукта — российский или open-source | B10: Open-source модели на GPU в российских облаках (Yandex Cloud, Selectel, Cloud.ru, VK Cloud): Qwen и DeepSeek для текста и зрения, GigaAM и T-one для распознавания русской речи, Silero для синтеза, Kandinsky для картинок. | C10: —
A11: AI внутри продукта — российский или open-source | B11: Голос и телефония: SaluteSpeech, Yandex SpeechKit, Voximplant, MTS Exolve. | C11: —
A12: Законы, которые стоит учитывать | B12: Закон об ИИ (243-ФЗ от 26.07.2026). Основная часть действует с 1 сентября 2026 года. Требования к маркировке AI-контента и к крупным моделям вступят в силу с 1 марта 2027 года. Площадки с аудиторией больше 500 тыс. в сутки должны дать техническую возможность предупреждать об AI-контенте. Подробности будут в подзаконных актах (разбор, Новая газета Европа). | C12: https://pravo163.ru/zakon-ob-iskusstvennom-intellekte/ https://novayagazeta.eu/articles/2026/07/09/gosduma-priniala-pervyi-v-rossii-zakon-reguliruiushchii-rabotu-ii
... A16: Законы, которые стоит учитывать | B16: Реклама: маркировка (ERID), обязательная возрастная маркировка контента (436-ФЗ). Законопроект о видеоиграх № 795581-8 с идентификацией игроков по состоянию на 2026 год не принят, но за ним стоит следить (ППТ.ру). | C16: https://ppt.ru/news/identifikatsiya-klientov/vvedut-markirovku-i-identifikatsiyu-igrokov-v-videoigrakh

Sheet Источники
A1: Группа | B1: Источник | C1: Ссылка
A2: Рынок и правила игры | B2: Битрикс24 — Telegram в 2026 | C2: =HYPERLINK("https://www.bitrix24.ru/journal/blokirovka-telegram/","https://www.bitrix24.ru/journal/blokirovka-telegram/") -> https://www.bitrix24.ru/journal/blokirovka-telegram/
A3: Рынок и правила игры | B3: vc.ru — июнь 2026: Telegram, MAX, ФАС | C3: =HYPERLINK("https://vc.ru/telegram/2974687-blokirovka-telegram-i-ischeznoveniye-max","https://vc.ru/telegram/2974687-blokirovka-telegram-i-ischeznoveniye-max") -> https://vc.ru/telegram/2974687-blokirovka-telegram-i-ischeznoveniye-max
A4: Рынок и правила игры | B4: ppc.world — WhatsApp | C4: =HYPERLINK("https://ppc.world/news/whatsapp-otklyuchat-v-2026-godu-telegram-trogat-ne-budut-deputat-gosdumy/","https://ppc.world/news/whatsapp-otklyuchat-v-2026-godu-telegram-trogat-ne-budut-deputat-gosdumy/") -> https://ppc.world/news/whatsapp-otklyuchat-v-2026-godu-telegram-trogat-ne-budut-deputat-gosdumy/
A5: Рынок и правила игры | B5: Sostav — MAX для бизнеса | C5: =HYPERLINK("https://www.sostav.ru/blogs/292093/95285","https://www.sostav.ru/blogs/292093/95285") -> https://www.sostav.ru/blogs/292093/95285
A6: Рынок и правила игры | B6: Т-Бизнес — MAX для бизнеса | C6: =HYPERLINK("https://secrets.tbank.ru/tehnologii/max-dlya-biznesa/","https://secrets.tbank.ru/tehnologii/max-dlya-biznesa/") -> https://secrets.tbank.ru/tehnologii/max-dlya-biznesa/
A7: Рынок и правила игры | B7: Медуза — школьные чаты в Max | C7: =HYPERLINK("https://meduza.io/news/2025/07/27/kommersant-soobschil-chto-shkolnye-chaty-v-shesti-regionah-rossii-perevedut-v-messendzher-max-v-tatarstane-perehod-podtverdili","https://meduza.io/news/2025/07/27/kommersant-soobschil-chto-shkolnye-chaty-v-shesti-regionah-rossii-perevedut-v-messendzher-max-v-tatarstane-perehod-podtverdili") -> https://meduza.io/news/2025/07/27/kommersant-soobschil-chto-shkolnye-chaty-v-shesti-regionah-rossii-perevedut-v-messendzher-max-v-tatarstane-perehod-podtverdili
A8: Рынок и правила игры | B8: WN Hub — Яндекс Игры, 45 млн игроков | C8: =HYPERLINK("https://wnhub.io/ru/news/monetization/item-47819","https://wnhub.io/ru/news/monetization/item-47819") -> https://wnhub.io/ru/news/monetization/item-47819
A9: Рынок и правила игры | B9: Яндекс Игры для разработчиков | C9: =HYPERLINK("https://yandex.ru/project/games/for-developers","https://yandex.ru/project/games/for-developers") -> https://yandex.ru/project/games/for-developers
A10: Рынок и правила игры | B10: ComNews — выручка игровой отрасли 2025 | C10: =HYPERLINK("https://www.comnews.ru/content/243534/2026-01-30/2026-w05/1008/moskva-ukrepila-liderstvo-proizvodstve-rossiyskikh-videoigr","https://www.comnews.ru/content/243534/2026-01-30/2026-w05/1008/moskva-ukrepila-liderstvo-proizvodstve-rossiyskikh-videoigr") -> https://www.comnews.ru/content/243534/2026-01-30/2026-w05/1008/moskva-ukrepila-liderstvo-proizvodstve-rossiyskikh-videoigr
A11: Рынок и правила игры | B11: ППТ.ру — законопроект о видеоиграх | C11: =HYPERLINK("https://ppt.ru/news/identifikatsiya-klientov/vvedut-markirovku-i-identifikatsiyu-igrokov-v-videoigrakh","https://ppt.ru/news/identifikatsiya-klientov/vvedut-markirovku-i-identifikatsiyu-igrokov-v-videoigrakh") -> https://ppt.ru/news/identifikatsiya-klientov/vvedut-markirovku-i-identifikatsiyu-igrokov-v-videoigrakh
A12: Рынок и правила игры | B12: Разбор закона об ИИ 243-ФЗ | C12: =HYPERLINK("https://pravo163.ru/zakon-ob-iskusstvennom-intellekte/","https://pravo163.ru/zakon-ob-iskusstvennom-intellekte/") -> https://pravo163.ru/zakon-ob-iskusstvennom-intellekte/
A13: Рынок и правила игры | B13: Новая газета Европа — закон об ИИ | C13: =HYPERLINK("https://novayagazeta.eu/articles/2026/07/09/gosduma-priniala-pervyi-v-rossii-zakon-reguliruiushchii-rabotu-ii","https://novayagazeta.eu/articles/2026/07/09/gosduma-priniala-pervyi-v-rossii-zakon-reguliruiushchii-rabotu-ii") -> https://novayagazeta.eu/articles/2026/07/09/gosduma-priniala-pervyi-v-rossii-zakon-reguliruiushchii-rabotu-ii
A14: Рынок и правила игры | B14: ППТ.ру — 289-ФЗ о платформенной экономике | C14: =HYPERLINK("https://ppt.ru/obzory/vstupaet-v-silu/federalnyy-zakon-31-07-2025-289-fz","https://ppt.ru/obzory/vstupaet-v-silu/federalnyy-zakon-31-07-2025-289-fz") -> https://ppt.ru/obzory/vstupaet-v-silu/federalnyy-zakon-31-07-2025-289-fz
A15: Рынок и правила игры | B15: ППТ.ру — 41-ФЗ | C15: =HYPERLINK("https://ppt.ru/amp/obzory/vstupaet-v-silu/federalnyy-zakon-01-04-2025-41-fz","https://ppt.ru/amp/obzory/vstupaet-v-silu/federalnyy-zakon-01-04-2025-41-fz") -> https://ppt.ru/amp/obzory/vstupaet-v-silu/federalnyy-zakon-01-04-2025-41-fz
A16: Рынок и правила игры | B16: Гарант — 41-ФЗ | C16: =HYPERLINK("https://www.garant.ru/news/1820251/","https://www.garant.ru/news/1820251/") -> https://www.garant.ru/news/1820251/
A17: Рынок и правила игры | B17: 3DNews — цены на модели, август 2026 | C17: =HYPERLINK("https://3dnews.ru/1147409","https://3dnews.ru/1147409") -> https://3dnews.ru/1147409
A18: Рынок и правила игры | B18: AdIndex — цены на модели | C18: =HYPERLINK("https://adindex.ru/news/digital/2026/08/25/348304.phtml","https://adindex.ru/news/digital/2026/08/25/348304.phtml") -> https://adindex.ru/news/digital/2026/08/25/348304.phtml
A19: Рынок и правила игры | B19: Тарифы GigaChat API | C19: =HYPERLINK("https://developers.sber.ru/docs/ru/gigachat/tariffs/legal-tariffs","https://developers.sber.ru/docs/ru/gigachat/tariffs/legal-tariffs") -> https://developers.sber.ru/docs/ru/gigachat/tariffs/legal-tariffs
A20: Рынок и правила игры | B20: vc.ru — оплата Duolingo из РФ | C20: =HYPERLINK("https://vc.ru/services/3012698-sposoby-oplaty-podpiski-duolingo-iz-rossii","https://vc.ru/services/3012698-sposoby-oplaty-podpiski-duolingo-iz-rossii") -> https://vc.ru/services/3012698-sposoby-oplaty-podpiski-duolingo-iz-rossii
A21: Рынок и правила игры | B21: Anti-Malware — ущерб от мошенников за 2025 | C21: =HYPERLINK("https://www.anti-malware.ru/news/2026-01-29-121598/48865","https://www.anti-malware.ru/news/2026-01-29-121598/48865") -> https://www.anti-malware.ru/news/2026-01-29-121598/48865
A22: Продукты и конкуренты | B22: Т—Ж — статистика «5 букв» | C22: =HYPERLINK("https://t-j.ru/5bukv-game-stat/","https://t-j.ru/5bukv-game-stat/") -> https://t-j.ru/5bukv-game-stat/
A23: Продукты и конкуренты | B23: Jackbox — как играть | C23: =HYPERLINK("https://www.jackboxgames.com/how-to","https://www.jackboxgames.com/how-to") -> https://www.jackboxgames.com/how-to
A24: Продукты и конкуренты | B24: Naked Science — GeoGuessr | C24: =HYPERLINK("https://naked-science.ru/article/media/onlaine-game-geoguessr","https://naked-science.ru/article/media/onlaine-game-geoguessr") -> https://naked-science.ru/article/media/onlaine-game-geoguessr
A25: Продукты и конкуренты | B25: RuStore — Калорика AI | C25: =HYPERLINK("https://www.rustore.ru/catalog/app/com.nutrisync.advanced","https://www.rustore.ru/catalog/app/com.nutrisync.advanced") -> https://www.rustore.ru/catalog/app/com.nutrisync.advanced
A26: Продукты и конкуренты | B26: RuStore — FoodWarz | C26: =HYPERLINK("https://www.rustore.ru/catalog/app/com.foodwarz.mobile","https://www.rustore.ru/catalog/app/com.foodwarz.mobile") -> https://www.rustore.ru/catalog/app/com.foodwarz.mobile
A27: Продукты и конкуренты | B27: Tasting Table — Timeleft | C27: =HYPERLINK("https://www.tastingtable.com/1859085/dinner-parties-with-strangers-timeleft","https://www.tastingtable.com/1859085/dinner-parties-with-strangers-timeleft") -> https://www.tastingtable.com/1859085/dinner-parties-with-strangers-timeleft
A28: Продукты и конкуренты | B28: Афиша — Stay Hungry | C28: =HYPERLINK("https://daily.afisha.ru/archive/gorod/archive/behind-stay-hungry/","https://daily.afisha.ru/archive/gorod/archive/behind-stay-hungry/") -> https://daily.afisha.ru/archive/gorod/archive/behind-stay-hungry/
A29: Продукты и конкуренты | B29: Storii — о StoryWorth | C29: =HYPERLINK("https://storii.com/blog/storyworth","https://storii.com/blog/storyworth") -> https://storii.com/blog/storyworth
A30: Продукты и конкуренты | B30: Joy Calls | C30: =HYPERLINK("https://www.homecaremag.com/news/joy-calls-launches-ai-phone-companion-seniors","https://www.homecaremag.com/news/joy-calls-launches-ai-phone-companion-seniors") -> https://www.homecaremag.com/news/joy-calls-launches-ai-phone-companion-seniors
A31: Продукты и конкуренты | B31: Meela | C31: =HYPERLINK("https://www.businesswire.com/news/home/20250911525548/en/Meela-Launches-Personalized-AI-Companion-to-Combat-Loneliness-Epidemic-Among-Seniors","https://www.businesswire.com/news/home/20250911525548/en/Meela-Launches-Personalized-AI-Companion-to-Combat-Loneliness-Epidemic-Among-Seniors") -> https://www.businesswire.com/news/home/20250911525548/en/Meela-Launches-Personalized-AI-Companion-to-Combat-Loneliness-Epidemic-Among-Seniors
A32: Продукты и конкуренты | B32: Rozetked — МТС и уведомления семье | C32: =HYPERLINK("https://rozetked.me/index.php/news/47910-analitika-bol-she-poloviny-rossiyan-ispol-zuyut-ii-servisy-cifrovoy-zaschity","https://rozetked.me/index.php/news/47910-analitika-bol-she-poloviny-rossiyan-ispol-zuyut-ii-servisy-cifrovoy-zaschity") -> https://rozetked.me/index.php/news/47910-analitika-bol-she-poloviny-rossiyan-ispol-zuyut-ii-servisy-cifrovoy-zaschity
A33: Продукты и конкуренты | B33: App Store — Laoshi AI | C33: =HYPERLINK("https://apps.apple.com/us/app/%D0%BA%D0%B8%D1%82%D0%B0%D0%B9%D1%81%D0%BA%D0%B8%D0%B9-%D1%8F%D0%B7%D1%8B%D0%BA-%D1%81-%D0%BB%D0%B0%D0%BE%D1%88%D0%B8/id1510215770?l=ru","https://apps.apple.com/us/app/%D0%BA%D0%B8%D1%82%D0%B0%D0%B9%D1%81%D0%BA%D0%B8%D0%B9-%D1%8F%D0%B7%D1%8B%D0%BA-%D1%81-%D0%BB%D0%B0%D0%BE%D1%88%D0%B8/id1510215770?l=ru") -> https://apps.apple.com/us/app/%D0%BA%D0%B8%D1%82%D0%B0%D0%B9%D1%81%D0%BA%D0%B8%D0%B9-%D1%8F%D0%B7%D1%8B%D0%BA-%D1%81-%D0%BB%D0%B0%D0%BE%D1%88%D0%B8/id1510215770?l=ru
A34: Продукты и конкуренты | B34: Yandex Cloud — кейс aiПушкин | C34: =HYPERLINK("https://yandex.cloud/ru/cases/aipushkin","https://yandex.cloud/ru/cases/aipushkin") -> https://yandex.cloud/ru/cases/aipushkin
A35: Продукты и конкуренты | B35: Сбер — GigaChat для учителей | C35: =HYPERLINK("https://developers.sber.ru/help/gigachat-api/ai-for-teachers","https://developers.sber.ru/help/gigachat-api/ai-for-teachers") -> https://developers.sber.ru/help/gigachat-api/ai-for-teachers
A36: Продукты и конкуренты | B36: App Store — ЧекаЧек | C36: =HYPERLINK("https://apps.apple.com/ru/app/id6471586789","https://apps.apple.com/ru/app/id6471586789") -> https://apps.apple.com/ru/app/id6471586789
A37: Продукты и конкуренты | B37: Правовед — претензии | C37: =HYPERLINK("https://pravoved.ru/documents/new/claim/","https://pravoved.ru/documents/new/claim/") -> https://pravoved.ru/documents/new/claim/
A38: Продукты и конкуренты | B38: Внесудебное банкротство через МФЦ | C38: =HYPERLINK("https://vitvet.com/articles/bankrotstvo/vnesudebnoe_bankrotstvo_mfc/","https://vitvet.com/articles/bankrotstvo/vnesudebnoe_bankrotstvo_mfc/") -> https://vitvet.com/articles/bankrotstvo/vnesudebnoe_bankrotstvo_mfc/
A39: Продукты и конкуренты | B39: Финуслуги — семейная выплата 2026 | C39: =HYPERLINK("https://finuslugi.ru/navigator/kak-ehto-rabotaet/stat_semeynaya-nalogovaya-vyplata-v-2026-godu","https://finuslugi.ru/navigator/kak-ehto-rabotaet/stat_semeynaya-nalogovaya-vyplata-v-2026-godu") -> https://finuslugi.ru/navigator/kak-ehto-rabotaet/stat_semeynaya-nalogovaya-vyplata-v-2026-godu
A40: Продукты и конкуренты | B40: Workspace — прототип AI-планировщика по России | C40: =HYPERLINK("https://workspace.ru/cases/puteshestviya-po-rossii-ot-neyroseti/","https://workspace.ru/cases/puteshestviya-po-rossii-ot-neyroseti/") -> https://workspace.ru/cases/puteshestviya-po-rossii-ot-neyroseti/
...
